<!-- Stanford Woofer Model

The state space is populated with joints in the order that they are
defined in this file.

The elements of the control variable s.d.ctrl correspond to:
[fr_x, fr_y, fr_ext,
fl_x, fl_y, fl_ext,
br_x, br_y, br_ext,
bl_x, bl_y, bl_ext]

fr = front-right
fl = front-left
br = back-right
bl = back-left
_x indicates rotation on the forward/back axis of the robot
_y indicates rotation on the left/right axis of the hip module
_ext indicates linear extension of the leg. Positive values = leg goes up
-->
<mujoco model="cheetah">
<compiler angle="radian" coordinate="local" inertiafromgeom="false"/>

<default>
    <joint armature="pupper_armature" solimplimit="pupper_joint_solimp" solreflimit="pupper_joint_solref" stiffness="0"/>
    <geom conaffinity="0" condim="3" contype="1" friction="pupper_friction .1 .1" rgba="0.8 0.6 .4 1" solimp="pupper_geom_solimp" solref="pupper_geom_solref"/>
    <position forcelimited="true"/>
</default>

<option>
    <flag sensornoise="disable"/>
</option>

<sensor>
    <accelerometer name="accel" noise="pupper_accel_noise" site="imu_site"/>
    <gyro name="gyro" noise="pupper_gyro_noise" site="imu_site"/>
</sensor>

<size nstack="300000" nuser_geom="1"/>

<!-- Took out gravity="0 0 -9.81" term-->
<option timestep="pupper_timestep"/>
<!-- <option gravity="0 0 0" timestep="pupper_timestep"/> -->
<asset>
    <texture builtin="gradient" height="100" rgb1="1 1 1" rgb2="0 0 0" type="skybox" width="100"/>
    <texture builtin="flat" height="1278" mark="cross" markrgb="1 1 1" name="texgeom" random="0.01" rgb1="0.8 0.6 0.4" rgb2="0.8 0.6 0.4" type="cube" width="127"/>
    <texture builtin="checker" height="100" name="texplane" rgb1="0 0 0" rgb2="0.8 0.8 0.8" type="2d" width="100"/>
    <material name="MatPlane" reflectance="0.5" shininess="1" specular="1" texrepeat="60 60" texture="texplane"/>
    <material name="geom" texture="texgeom" texuniform="true"/>
</asset>

<worldbody>
    <light cutoff="100" diffuse="1 1 1" dir="-0 0 -1.3" directional="true" exponent="1" pos="0 0 1.3" specular=".1 .1 .1"/>
    <geom conaffinity="1" condim="3" material="MatPlane" name="floor" pos="0 0 0" rgba="0.8 0.9 0.8 1" size="40 40 40" type="plane"/>
    <body name="torso" pos="pupper_start_position">
        <camera name="track" mode="trackcom" pos="0 -2 0.3" xyaxes="1 0 0 0 0 1"/>
        <joint armature="0" axis="1 0 0" damping="0" limited="false" name="rootx" pos="0 0 0" stiffness="0" type="free"/>
        <inertial pos="0 0 0" mass="pupper_frame_mass" diaginertia="pupper_frame_inertia"/>
        <geom pos="0 0 0" name="torso" size="pupper_half_size" type="box"/>
        <site name="imu_site" pos="0 0 0" size=".01 .01 .01" type="box"/>

        <body name="fr_module" pos="pupper_leg_fb -pupper_leg_lr 0">
            <geom pos="0 -pupper_hip_offset 0" name="fr_block" type="box" size="pupper_hip_box" rgba="0.6 0.8 .4 1"/>
            <joint axis="1 0 0" name="fr_x" pos="0 0 0" limited="true" range="pupper_joint_range" type="hinge" damping="pupper_rev_damping"/>
            <inertial pos="0 0 0" mass="pupper_module_mass" diaginertia="pupper_module_inertia"/>
            <body name="fr" pos="0 -pupper_abduction_offset 0">
                <joint axis="0 1 0" name="fr_y" pos="0 0 0" limited="true" range="pupper_joint_range" type="hinge" damping="pupper_rev_damping"/>
                <joint axis="0 0 1" name="fr_r" pos = "0 0 0" limited="true" range="pupper_ext_range" type = "slide" damping="pupper_prism_damping"/>
                <inertial pos="0 0 0" mass="pupper_leg_mass" diaginertia="pupper_leg_inertia"/>
                <site name="fr_force_site" pos="pupper_force_geom" size=".01 .01 .01" type="box"/>
                <geom axisangle="0 1 0 0" name="fr" fromto="pupper_leg_geom" size="pupper_leg_radius" type="capsule" rgba = "1 0 0 0.5" density="50"/>
            </body>
        </body>

        <body name="fl_module" pos="pupper_leg_fb pupper_leg_lr 0">
            <geom pos = "0 pupper_hip_offset 0" name="fl_block" type="box" size="pupper_hip_box" rgba="0.6 0.8 .4 1"/>
            <joint axis="1 0 0" name="fl_x" pos="0 0 0" limited="true" range="pupper_joint_range" type="hinge" damping="pupper_rev_damping"/>
            <inertial pos="0 0 0" mass="pupper_module_mass" diaginertia="pupper_module_inertia"/>
            <body name="fl" pos="0 pupper_abduction_offset 0">
                <joint axis="0 1 0" name="fl_y" pos="0 0 0" limited="true" range="pupper_joint_range" type="hinge" damping="pupper_rev_damping"/>
                <joint axis="0 0 1" name="fl_r" pos = "0 0 0" limited="true" range="pupper_ext_range" type = "slide" damping="pupper_prism_damping"/>
                <inertial pos="0 0 0" mass="pupper_leg_mass" diaginertia="pupper_leg_inertia"/>
                <site name="fl_force_site" pos="pupper_force_geom" size=".01 .01 .01" type="box"/>
                <geom axisangle="0 1 0 0" name="fl" fromto="pupper_leg_geom" size="pupper_leg_radius" type="capsule" rgba = "1 0 0 0.5" density="50"/>
            </body>
        </body>

        <body name="br_module" pos="-pupper_leg_fb -pupper_leg_lr 0">
            <geom pos = "0 -pupper_hip_offset 0" name="br_block" type="box" size="pupper_hip_box" rgba="0.6 0.8 .4 1"/>
            <joint axis="1 0 0" name="br_x" pos="0 0 0" limited="true" range="pupper_joint_range" type="hinge" damping="pupper_rev_damping"/>
            <inertial pos="0 0 0" mass="pupper_module_mass" diaginertia="pupper_module_inertia"/>
            <body name="br" pos="0 -pupper_abduction_offset 0">
                <joint axis="0 1 0" name="br_y" pos="0 0 0" limited="true" range="pupper_joint_range" type="hinge" damping="pupper_rev_damping"/>
                <joint axis="0 0 1" name="br_r" pos = "0 0 0" limited="true" range="pupper_ext_range" type = "slide" damping="pupper_prism_damping"/>
                <inertial pos="0 0 0" mass="pupper_leg_mass" diaginertia="pupper_leg_inertia"/>
                <site name="br_force_site" pos="pupper_force_geom" size=".01 .01 .01" type="box"/>
                <geom axisangle="0 1 0 0" name="br" fromto="pupper_leg_geom" size="pupper_leg_radius" type="capsule" rgba = "1 0 0 0.5" density="50"/>
            </body>
        </body>

        <body name="bl_module" pos="-pupper_leg_fb pupper_leg_lr 0">
            <geom pos = "0 pupper_hip_offset 0" name="bl_block" type="box" size="pupper_hip_box" rgba="0.6 0.8 .4 1"/>
            <joint axis="1 0 0" name="bl_x" pos="0 0 0" limited="true" range="pupper_joint_range" type="hinge" damping="pupper_rev_damping"/>
            <inertial pos="0 0 0" mass="pupper_module_mass" diaginertia="pupper_module_inertia"/>
            <body name="bl" pos="0 pupper_abduction_offset 0">
                <joint axis="0 1 0" name="bl_y" pos="0 0 0" limited="true" range="pupper_joint_range" type="hinge" damping="pupper_rev_damping"/>
                <joint axis="0 0 1" name="bl_r" pos = "0 0 0" limited="true" range="pupper_ext_range" type = "slide" damping="pupper_prism_damping"/>
                <inertial pos="0 0 0" mass="pupper_leg_mass" diaginertia="pupper_leg_inertia"/>
                <site name="bl_force_site" pos="pupper_force_geom" size=".01 .01 .01" type="box"/>
                <geom axisangle="0 1 0 0" name="bl" fromto="pupper_leg_geom" size="pupper_leg_radius" type="capsule" rgba = "1 0 0 0.5" density="50"/>
            </body>
        </body>
    </body>
</worldbody>

<actuator>
    <position gear="1" joint="fr_x" name="fr_x" kp="pupper_rev_kp" forcerange="pupper_rev_torque_range"/>
    <position gear="1" joint="fr_y" name="fr_y" kp="pupper_rev_kp" forcerange="pupper_rev_torque_range"/>
    <position gear="1" joint="fr_r" name="fr_r" kp="pupper_prism_kp" forcerange="pupper_prism_force_range"/>

    <position gear="1" joint="fl_x" name="fl_x" kp="pupper_rev_kp" forcerange="pupper_rev_torque_range"/>
    <position gear="1" joint="fl_y" name="fl_y" kp="pupper_rev_kp" forcerange="pupper_rev_torque_range"/>
    <position gear="1" joint="fl_r" name="fl_r" kp="pupper_prism_kp" forcerange="pupper_prism_force_range"/>

    <position gear="1" joint="br_x" name="br_x" kp="pupper_rev_kp" forcerange="pupper_rev_torque_range"/>
    <position gear="1" joint="br_y" name="br_y" kp="pupper_rev_kp" forcerange="pupper_rev_torque_range"/>
    <position gear="1" joint="br_r" name="br_r" kp="pupper_prism_kp" forcerange="pupper_prism_force_range"/>

    <position gear="1" joint="bl_x" name="bl_x" kp="pupper_rev_kp" forcerange="pupper_rev_torque_range"/>
    <position gear="1" joint="bl_y" name="bl_y" kp="pupper_rev_kp" forcerange="pupper_rev_torque_range"/>
    <position gear="1" joint="bl_r" name="bl_r" kp="pupper_prism_kp" forcerange="pupper_prism_force_range"/>
    </actuator>
</mujoco>
